Workbook

Sheet nodeId
A1: nodeNum | B1: City | C1: type | D1: fi_0 | E1: oi | F1: si_num | G1: capacity | H1: si_1 | I1: factor | J1: fi | K1: di | L1: si | M1: supply factor
A2: 0 | B2: Acton | C2: C | F2: 52750 | H2: =F2*25 -> 1318750 | L2: =H2*$M$2 -> 1318750 | M2: 1
A3: 1 | B3: Arnprior | C3: C | F3: 29860 | H3: =F3*25 -> 746500 | L3: =H3*$M$2 -> 746500
A4: 2 | B4: Arthur | C4: C | F4: 44602 | H4: =F4*25 -> 1115050 | L4: =H4*$M$2 -> 1115050
A5: 3 | B5: Aurora | C5: C | F5: 110396 | H5: =F5*25 -> 2759900 | L5: =H5*$M$2 -> 2759900
A6: 4 | B6: Beaverton | C6: C | F6: 77661 | H6: =F6*25 -> 1941525 | L6: =H6*$M$2 -> 1941525
A7: 5 | B7: Bowmanville | C7: C | F7: 77661 | H7: =F7*25 -> 1941525 | L7: =H7*$M$2 -> 1941525
A8: 6 | B8: Bradford | C8: C | F8: 103343 | H8: =F8*25 -> 2583575 | L8: =H8*$M$2 -> 2583575
A9: 7 | B9: Brampton | C9: C | F9: 371033 | H9: =F9*25 -> 9275825 | L9: =H9*$M$2 -> 9275825
A10: 8 | B10: Brantford | C10: C | F10: 83809 | H10: =F10*25 -> 2095225 | L10: =H10*$M$2 -> 2095225
A11: 9 | B11: Caistor Centre | C11: C | F11: 4704 | H11: =F11*25 -> 117600 | L11: =H11*$M$2 -> 117600
A12: 10 | B12: Caledon | C12: C | F12: 371033 | H12: =F12*25 -> 9275825 | L12: =H12*$M$2 -> 9275825
A13: 11 | B13: Cambridge | C13: C | F13: 107823 | H13: =F13*25 -> 2695575 | L13: =H13*$M$2 -> 2695575
A14: 12 | B14: Clarence Creek | C14: C | F14: 110396 | H14: =F14*25 -> 2759900 | L14: =H14*$M$2 -> 2759900
... A78: 76 | B78: Windsor | C78: C | F78: 56665 | H78: =F78*25 -> 1416625 | L78: =H78*$M$2 -> 1416625
A79: 77 | B79: Toronto | C79: R | D79: 2000000 | E79: 0 | G79: 643780300000 | I79: 1.0092964 | J79: =D79*I79 -> 2018592.8
A80: 78 | B80: Ottawa | C80: R | D80: 2000000 | E80: 0 | G80: 643780300000 | I80: 1.0062721 | J80: =D80*I80 -> 2012544.2
A81: 79 | B81: Mississauga | C81: R | D81: 2000000 | E81: 0 | G81: 643780300000 | I81: 1.0179347 | J81: =D81*I81 -> 2035869.4
A82: 80 | B82: Brampton | C82: R | D82: 2000000 | E82: 0 | G82: 643780300000 | I82: 1.0179347 | J82: =D82*I82 -> 2035869.4
A83: 81 | B83: Hamilton | C83: R | D83: 2000000 | E83: 0 | G83: 643780300000 | I83: 1.0178776 | J83: =D83*I83 -> 2035755.2
A84: 82 | B84: London | C84: R | D84: 2000000 | E84: 0 | G84: 643780300000 | I84: 1.0098273 | J84: =D84*I84 -> 2019654.7
A85: 83 | B85: Markham | C85: R | D85: 2000000 | E85: 0 | G85: 643780300000 | I85: 1.0178776 | J85: =D85*I85 -> 2035755.2
A86: 84 | B86: Vaughan | C86: R | D86: 2000000 | E86: 0 | G86: 643780300000 | I86: 1.0082075 | J86: =D86*I86 -> 2016415
A87: 85 | B87: Kitchener | C87: R | D87: 2000000 | E87: 0 | G87: 643780300000 | I87: 1.0126383 | J87: =D87*I87 -> 2025276.7
A88: 86 | B88: Windsor | C88: R | D88: 2000000 | E88: 0 | G88: 643780300000 | I88: 1.0109401 | J88: =D88*I88 -> 2021880.1
A89: 87 | B89: Oakville | C89: R | D89: 2000000 | E89: 0 | G89: 643780300000 | I89: 1.0273074 | J89: =D89*I89 -> 2054614.9
A90: 88 | B90: Richmond Hill | C90: R | D90: 2000000 | E90: 0 | G90: 643780300000 | I90: 1.0178776 | J90: =D90*I90 -> 2035755.2
... A179: 177 | B179: Penetanguishene | C179: R | D179: 2000000 | E179: 0 | G179: 643780300000 | I179: 1.0082075 | J179: =D179*I179 -> 2016415
A180: 178 | B180: Fiat Chrysler Automobiles, Brampton Assembly Plant | C180: M | K180: =SUM($L$2:$L$78)*0.8/18 -> 7153114.4
A181: 179 | B181: Stellantis (Chrysler) Windsor | C181: M | K181: =SUM($L$2:$L$78)*0.8/18 -> 7153114.4
A182: 180 | B182: Oakville Assembly Complex, Ford Motor Company of Canada, Limited | C182: M | K182: =SUM($L$2:$L$78)*0.8/18 -> 7153114.4
A183: 181 | B183: St. Thomas Assembly Plant | C183: M | K183: =SUM($L$2:$L$78)*0.8/18 -> 7153114.4
A184: 182 | B184: Ford Motor Co. Windsor Engine Plant | C184: M | K184: =SUM($L$2:$L$78)*0.8/18 -> 7153114.4
A185: 183 | B185: Ford | C185: M | K185: =SUM($L$2:$L$78)*0.8/18 -> 7153114.4
A186: 184 | B186: Oakville Assembly Complex, Ford Motor Company of Canada, Limited | C186: M | K186: =SUM($L$2:$L$78)*0.8/18 -> 7153114.4
A187: 185 | B187: Ford Motor Co of Canada Ltd | C187: M | K187: =SUM($L$2:$L$78)*0.8/18 -> 7153114.4
A188: 186 | B188: GM Oshawa Assembly | C188: M | K188: =SUM($L$2:$L$78)*0.8/18 -> 7153114.4
A189: 187 | B189: General Motors of Canada Company | C189: M | K189: =SUM($L$2:$L$78)*0.8/18 -> 7153114.4
A190: 188 | B190: GM CAMI Assembly | C190: M | K190: =SUM($L$2:$L$78)*0.8/18 -> 7153114.4
A191: 189 | B191: Honda of Canada Mfg. | C191: M | K191: =SUM($L$2:$L$78)*0.8/18 -> 7153114.4
...

Sheet Time_nodeID

Sheet Node_10_2
A1: nodeNum | B1: City | C1: type | D1: f_og | E1: factor | F1: f_i | G1: capacity | H1: o_i | I1: d_1 | J1: d_2 | K1: d_3 | L1: d_4 | M1: d_5 | N1: si | O1: si_num | P1: s_1 | Q1: s_2 | R1: s_3 | S1: s_4 | T1: s_5
A2: 0 | B2: Acton | C2: C | N2: 52750 | O2: =N2*25 -> 1318750 | P2: 1261476.8 | Q2: 1338346.5 | R2: 1384874.5 | S2: 1489897 | T2: 1557955.8
A3: 1 | B3: Arnprior | C3: C | N3: 29860 | O3: =N3*25 -> 746500 | P3: 792590.65 | Q3: 690543.33 | R3: 715763.19 | S3: 824784.19 | T3: 734647.83
A4: 2 | B4: Arthur | C4: C | N4: 44602 | O4: =N4*25 -> 1115050 | P4: 1132285.4 | Q4: 1148141.2 | R4: 1397594.9 | S4: 1110342 | T4: 1080435.6
A5: 3 | B5: Aurora | C5: C | N5: 110396 | O5: =N5*25 -> 2759900 | P5: 3146349.3 | Q5: 2454838 | R5: 2744802.2 | S5: 2421977.9 | T5: 2280518.1
A6: 4 | B6: Beaverton | C6: C | N6: 77661 | O6: =N6*25 -> 1941525 | P6: 2000595.1 | Q6: 2036691 | R6: 1819650.6 | S6: 2293933.6 | T6: 1459759.8
A7: 5 | B7: Bowmanville | C7: C | N7: 77661 | O7: =N7*25 -> 1941525 | P7: 2005417.9 | Q7: 1997816.1 | R7: 2177575.3 | S7: 1892014.1 | T7: 1881354.5
A8: 6 | B8: Bradford | C8: C | N8: 103343 | O8: =N8*25 -> 2583575 | P8: 2467199.2 | Q8: 2651596.6 | R8: 2764535.5 | S8: 2165230.3 | T8: 3028606
A9: 7 | B9: Brampton | C9: C | N9: 371033 | O9: =N9*25 -> 9275825 | P9: 9213869 | Q9: 7823851.7 | R9: 9521632.6 | S9: 8979472.3 | T9: 8233982.5
A10: 8 | B10: Brantford | C10: C | N10: 83809 | O10: =N10*25 -> 2095225 | P10: 2259015.1 | Q10: 1988340.4 | R10: 2142791.7 | S10: 2205250.1 | T10: 2125387.6
A11: 9 | B11: Caistor Centre | C11: C | N11: 4704 | O11: =N11*25 -> 117600 | P11: 125242.7 | Q11: 125614.95 | R11: 108794.98 | S11: 105736.1 | T11: 85840.964
A12: 10 | B12: Caledon | C12: C | N12: 371033 | O12: =N12*25 -> 9275825 | P12: 9206180.2 | Q12: 10298203 | R12: 7841041.7 | S12: 8608089.1 | T12: 10085081
A13: 11 | B13: Cambridge | C13: C | N13: 107823 | O13: =N13*25 -> 2695575 | P13: 2903330.2 | Q13: 2517450.5 | R13: 2185642.4 | S13: 2778500.8 | T13: 2969388.6
... A78: 76 | B78: Windsor | C78: C | N78: 56665 | O78: =N78*25 -> 1416625 | P78: 1547033.7 | Q78: 1436515.6 | R78: 1421102.4 | S78: 1487461.5 | T78: 1534293.6
A79: 77 | B79: Toronto | C79: R | D79: 2000000 | E79: 1.0092964 | F79: =D79*E79 -> 2018592.8 | G79: 6000000000 | H79: 0.02
A80: 78 | B80: Ottawa | C80: R | D80: 2000000 | E80: 1.0062721 | F80: =D80*E80 -> 2012544.2 | G80: 6000000000 | H80: 0.02
A81: 79 | B81: Mississauga | C81: R | D81: 2000000 | E81: 1.0179347 | F81: =D81*E81 -> 2035869.4 | G81: 6000000000 | H81: 0.02
A82: 80 | B82: Brampton | C82: R | D82: 2000000 | E82: 1.0179347 | F82: =D82*E82 -> 2035869.4 | G82: 6000000000 | H82: 0.02
A83: 81 | B83: Hamilton | C83: R | D83: 2000000 | E83: 1.0178776 | F83: =D83*E83 -> 2035755.2 | G83: 6000000000 | H83: 0.02
A84: 82 | B84: London | C84: R | D84: 2000000 | E84: 1.0098273 | F84: =D84*E84 -> 2019654.7 | G84: 6000000000 | H84: 0.02
A85: 83 | B85: Markham | C85: R | D85: 2000000 | E85: 1.0178776 | F85: =D85*E85 -> 2035755.2 | G85: 6000000000 | H85: 0.02
A86: 84 | B86: Vaughan | C86: R | D86: 2000000 | E86: 1.0082075 | F86: =D86*E86 -> 2016415 | G86: 6000000000 | H86: 0.02
A87: 85 | B87: Kitchener | C87: R | D87: 2000000 | E87: 1.0126383 | F87: =D87*E87 -> 2025276.7 | G87: 6000000000 | H87: 0.02
A88: 86 | B88: Windsor | C88: R | D88: 2000000 | E88: 1.0109401 | F88: =D88*E88 -> 2021880.1 | G88: 6000000000 | H88: 0.02
A89: 87 | B89: Oakville | C89: R | D89: 2000000 | E89: 1.0273074 | F89: =D89*E89 -> 2054614.9 | G89: 6000000000 | H89: 0.02
A90: 88 | B90: Richmond Hill | C90: R | D90: 2000000 | E90: 1.0178776 | F90: =D90*E90 -> 2035755.2 | G90: 6000000000 | H90: 0.02
... A179: 177 | B179: Penetanguishene | C179: R | D179: 2000000 | E179: 1.0082075 | F179: =D179*E179 -> 2016415 | G179: 6000000000 | H179: 0.02
A180: 178 | B180: Fiat Chrysler Automobiles, Brampton Assembly Plant | C180: M | I180: =SUM(P2:P78)*0.8/18 -> 6920059.5 | J180: =SUM(Q2:Q78)*0.8/18 -> 7159085.9 | K180: =SUM(R2:R78)*0.8/18 -> 7142063 | L180: =SUM(S2:S78)*0.8/18 -> 7275295.4 | M180: =SUM(T2:T78)*0.8/18 -> 7158427.6
A181: 179 | B181: Stellantis (Chrysler) Windsor | C181: M | I181: 6920059.5 | J181: 7159085.9 | K181: 7142063 | L181: 7275295.4 | M181: 7158427.6
A182: 180 | B182: Oakville Assembly Complex, Ford Motor Company of Canada, Limited | C182: M | I182: 6920059.5 | J182: 7159085.9 | K182: 7142063 | L182: 7275295.4 | M182: 7158427.6
A183: 181 | B183: St. Thomas Assembly Plant | C183: M | I183: 6920059.5 | J183: 7159085.9 | K183: 7142063 | L183: 7275295.4 | M183: 7158427.6
A184: 182 | B184: Ford Motor Co. Windsor Engine Plant | C184: M | I184: 6920059.5 | J184: 7159085.9 | K184: 7142063 | L184: 7275295.4 | M184: 7158427.6
A185: 183 | B185: Ford | C185: M | I185: 6920059.5 | J185: 7159085.9 | K185: 7142063 | L185: 7275295.4 | M185: 7158427.6
A186: 184 | B186: Oakville Assembly Complex, Ford Motor Company of Canada, Limited | C186: M | I186: 6920059.5 | J186: 7159085.9 | K186: 7142063 | L186: 7275295.4 | M186: 7158427.6
A187: 185 | B187: Ford Motor Co of Canada Ltd | C187: M | I187: 6920059.5 | J187: 7159085.9 | K187: 7142063 | L187: 7275295.4 | M187: 7158427.6
A188: 186 | B188: GM Oshawa Assembly | C188: M | I188: 6920059.5 | J188: 7159085.9 | K188: 7142063 | L188: 7275295.4 | M188: 7158427.6
A189: 187 | B189: General Motors of Canada Company | C189: M | I189: 6920059.5 | J189: 7159085.9 | K189: 7142063 | L189: 7275295.4 | M189: 7158427.6
A190: 188 | B190: GM CAMI Assembly | C190: M | I190: 6920059.5 | J190: 7159085.9 | K190: 7142063 | L190: 7275295.4 | M190: 7158427.6
A191: 189 | B191: Honda of Canada Mfg. | C191: M | I191: 6920059.5 | J191: 7159085.9 | K191: 7142063 | L191: 7275295.4 | M191: 7158427.6
A192: 190 | B192: Honda of Canada Manufacturing Gate B Rafid | C192: M | I192: 6920059.5 | J192: 7159085.9 | K192: 7142063 | L192: 7275295.4 | M192: 7158427.6
...

Sheet Node_stochastic_10
A1: nodeNum | B1: City | C1: type | D1: f_og | E1: factor | F1: f_i | G1: capacity | H1: o_i | I1: d_1 | J1: d_2 | K1: d_3 | L1: d_4 | M1: d_5 | N1: d_6 | O1: d_7 | P1: d_8 | Q1: d_9 | R1: d_10 | S1: d_11 | T1: d_12 | U1: d_13 | V1: d_14 | W1: d_15 | X1: d_16 | Y1: d_17 | Z1: d_18 | AA1: d_19 | AB1: d_20 | AC1: si | AD1: si_num | AE1: s_1 | AF1: s_2 | AG1: s_3 | AH1: s_4 | AI1: s_5 | AJ1: s_6 | AK1: s_7 | AL1: s_8 | AM1: s_9 | AN1: s_10 | AO1: s_11 | AP1: s_12 | AQ1: s_13 | AR1: s_14 | AS1: s_15 | AT1: s_16 | AU1: s_17 | AV1: s_18 | AW1: s_19 | AX1: s_20
A2: 0 | B2: Acton | C2: C | AC2: 52750 | AD2: =AC2*25 -> 1318750 | AE2: 1319210.5 | AF2: 1318043.8 | AG2: 1319137 | AH2: 1318914.8 | AI2: 1318930.7 | AJ2: 1318519.6 | AK2: 1319095.7 | AL2: 1319161.3 | AM2: 1318811.2 | AN2: 1319158.3 | AO2: 1318556.3 | AP2: 1317891.7 | AQ2: 1317725.8 | AR2: 1318648.5 | AS2: 1318225.2 | AT2: 1318018.6 | AU2: 1318737.9 | AV2: 1318005.2 | AW2: 1318640.8 | AX2: 1318872.1
A3: 1 | B3: Arnprior | C3: C | AC3: 29860 | AD3: =AC3*25 -> 746500 | AE3: 746810.62 | AF3: 746406.2 | AG3: 746409.4 | AH3: 746237.1 | AI3: 746321.48 | AJ3: 746110.7 | AK3: 746859.45 | AL3: 746194.71 | AM3: 746493.01 | AN3: 746617.32 | AO3: 746459.79 | AP3: 746594.35 | AQ3: 746614.41 | AR3: 746111.06 | AS3: 746157.15 | AT3: 746066.4 | AU3: 746372.88 | AV3: 746637.26 | AW3: 746241.22 | AX3: 745907.01
A4: 2 | B4: Arthur | C4: C | AC4: 44602 | AD4: =AC4*25 -> 1115050 | AE4: 1115210.8 | AF4: 1115286.8 | AG4: 1114858.8 | AH4: 1114796.9 | AI4: 1115046.4 | AJ4: 1114979.1 | AK4: 1115136.3 | AL4: 1114917.4 | AM4: 1114817.9 | AN4: 1114702.3 | AO4: 1115432 | AP4: 1114740.6 | AQ4: 1114936.4 | AR4: 1115690.5 | AS4: 1114566.3 | AT4: 1115610.9 | AU4: 1114934.4 | AV4: 1115076.1 | AW4: 1115393.2 | AX4: 1114779.4
A5: 3 | B5: Aurora | C5: C | AC5: 110396 | AD5: =AC5*25 -> 2759900 | AE5: 2758813.4 | AF5: 2759157 | AG5: 2759671.6 | AH5: 2759554.4 | AI5: 2760036.2 | AJ5: 2760837.5 | AK5: 2760037.7 | AL5: 2759970.2 | AM5: 2758937 | AN5: 2759618.4 | AO5: 2759237.8 | AP5: 2760862.7 | AQ5: 2759656.6 | AR5: 2759824.3 | AS5: 2759699.2 | AT5: 2760962.5 | AU5: 2759674.7 | AV5: 2760210.3 | AW5: 2760882 | AX5: 2759683
A6: 4 | B6: Beaverton | C6: C | AC6: 77661 | AD6: =AC6*25 -> 1941525 | AE6: 1942083.6 | AF6: 1941274.4 | AG6: 1941257.8 | AH6: 1941474.8 | AI6: 1941333.1 | AJ6: 1941782.4 | AK6: 1941787.4 | AL6: 1941377 | AM6: 1941449.7 | AN6: 1941423.4 | AO6: 1940850.1 | AP6: 1940537.4 | AQ6: 1942395.9 | AR6: 1942020 | AS6: 1941184.6 | AT6: 1940789.2 | AU6: 1941608.3 | AV6: 1940738.2 | AW6: 1941366.3 | AX6: 1940643.5
A7: 5 | B7: Bowmanville | C7: C | AC7: 77661 | AD7: =AC7*25 -> 1941525 | AE7: 1941715.7 | AF7: 1940855.4 | AG7: 1941161.4 | AH7: 1942243 | AI7: 1941832.7 | AJ7: 1941417.7 | AK7: 1940949.2 | AL7: 1941340.9 | AM7: 1942082.9 | AN7: 1941956.4 | AO7: 1941939.2 | AP7: 1941473.2 | AQ7: 1941072.7 | AR7: 1941666.3 | AS7: 1941666.6 | AT7: 1941474.3 | AU7: 1941374.4 | AV7: 1942249.2 | AW7: 1941167.9 | AX7: 1941722.4
A8: 6 | B8: Bradford | C8: C | AC8: 103343 | AD8: =AC8*25 -> 2583575 | AE8: 2583365.8 | AF8: 2582533.2 | AG8: 2583836.4 | AH8: 2583690.1 | AI8: 2583039.3 | AJ8: 2584273.6 | AK8: 2584011.9 | AL8: 2583885.9 | AM8: 2584222.4 | AN8: 2583283.8 | AO8: 2584349.3 | AP8: 2584468.8 | AQ8: 2583314.3 | AR8: 2582800.2 | AS8: 2582962.6 | AT8: 2584475 | AU8: 2583961.6 | AV8: 2584229 | AW8: 2583699.6 | AX8: 2582743.7
A9: 7 | B9: Brampton | C9: C | AC9: 371033 | AD9: =AC9*25 -> 9275825 | AE9: 9276830.5 | AF9: 9274463.1 | AG9: 9276825.1 | AH9: 9276305.9 | AI9: 9274880.7 | AJ9: 9275540.7 | AK9: 9275306.3 | AL9: 9276056.5 | AM9: 9275990.9 | AN9: 9276261.8 | AO9: 9274938.1 | AP9: 9276633.7 | AQ9: 9276400.8 | AR9: 9274888.4 | AS9: 9275680.7 | AT9: 9276892.5 | AU9: 9274344.7 | AV9: 9276898.2 | AW9: 9276728.5 | AX9: 9274819
A10: 8 | B10: Brantford | C10: C | AC10: 83809 | AD10: =AC10*25 -> 2095225 | AE10: 2095114.7 | AF10: 2094862.8 | AG10: 2095098.5 | AH10: 2094296.1 | AI10: 2094507.6 | AJ10: 2095304.6 | AK10: 2094915.7 | AL10: 2094675 | AM10: 2095099.4 | AN10: 2094867.2 | AO10: 2094971.2 | AP10: 2094758.9 | AQ10: 2095524.7 | AR10: 2095981.4 | AS10: 2094325.2 | AT10: 2094913 | AU10: 2095332 | AV10: 2096012.5 | AW10: 2095610.2 | AX10: 2094631.8
A11: 9 | B11: Caistor Centre | C11: C | AC11: 4704 | AD11: =AC11*25 -> 117600 | AE11: 117700.36 | AF11: 117522.79 | AG11: 117599 | AH11: 117591.03 | AI11: 117642.36 | AJ11: 117571.5 | AK11: 117582.62 | AL11: 117620.83 | AM11: 117588.77 | AN11: 117559.65 | AO11: 117650.75 | AP11: 117783.5 | AQ11: 117584.44 | AR11: 117527.05 | AS11: 117666.15 | AT11: 117578.73 | AU11: 117443.34 | AV11: 117701.79 | AW11: 117569.72 | AX11: 117606.06
A12: 10 | B12: Caledon | C12: C | AC12: 371033 | AD12: =AC12*25 -> 9275825 | AE12: 9275966.6 | AF12: 9275204.5 | AG12: 9275980.2 | AH12: 9275984 | AI12: 9275707.1 | AJ12: 9278038.2 | AK12: 9275884.1 | AL12: 9275255.8 | AM12: 9275078 | AN12: 9276313.9 | AO12: 9275752.9 | AP12: 9275715.6 | AQ12: 9275976.5 | AR12: 9276441.4 | AS12: 9275644 | AT12: 9276965.5 | AU12: 9275211.5 | AV12: 9276085.9 | AW12: 9274483.8 | AX12: 9277161
A13: 11 | B13: Cambridge | C13: C | AC13: 107823 | AD13: =AC13*25 -> 2695575 | AE13: 2696185.1 | AF13: 2695730 | AG13: 2694476.6 | AH13: 2695367.8 | AI13: 2696045.3 | AJ13: 2695212.2 | AK13: 2695810.4 | AL13: 2694989.9 | AM13: 2694906.5 | AN13: 2696130 | AO13: 2695263.4 | AP13: 2694601 | AQ13: 2695363.7 | AR13: 2696044.2 | AS13: 2695711.5 | AT13: 2694771.8 | AU13: 2695232.9 | AV13: 2695558.8 | AW13: 2695664 | AX13: 2694371.6
... A78: 76 | B78: Windsor | C78: C | AC78: 56665 | AD78: =AC78*25 -> 1416625 | AE78: 1416804.5 | AF78: 1416504.8 | AG78: 1416738.2 | AH78: 1416523.7 | AI78: 1416853.1 | AJ78: 1417495.8 | AK78: 1415982.3 | AL78: 1416268.4 | AM78: 1417313.5 | AN78: 1416383.8 | AO78: 1416375.3 | AP78: 1417250.5 | AQ78: 1416109.3 | AR78: 1416735 | AS78: 1416779 | AT78: 1416389.3 | AU78: 1415880 | AV78: 1417293.3 | AW78: 1416910.5 | AX78: 1416839.6
A79: 77 | B79: Toronto | C79: R | D79: 2000000 | E79: 1.0092964 | F79: =D79*E79 -> 2018592.8 | G79: 6000000000 | H79: 0
A80: 78 | B80: Ottawa | C80: R | D80: 2000000 | E80: 1.0062721 | F80: =D80*E80 -> 2012544.2 | G80: 6000000000 | H80: 0
A81: 79 | B81: Mississauga | C81: R | D81: 2000000 | E81: 1.0179347 | F81: =D81*E81 -> 2035869.4 | G81: 6000000000 | H81: 0
A82: 80 | B82: Brampton | C82: R | D82: 2000000 | E82: 1.0179347 | F82: =D82*E82 -> 2035869.4 | G82: 6000000000 | H82: 0
A83: 81 | B83: Hamilton | C83: R | D83: 2000000 | E83: 1.0178776 | F83: =D83*E83 -> 2035755.2 | G83: 6000000000 | H83: 0
A84: 82 | B84: London | C84: R | D84: 2000000 | E84: 1.0098273 | F84: =D84*E84 -> 2019654.7 | G84: 6000000000 | H84: 0
A85: 83 | B85: Markham | C85: R | D85: 2000000 | E85: 1.0178776 | F85: =D85*E85 -> 2035755.2 | G85: 6000000000 | H85: 0
A86: 84 | B86: Vaughan | C86: R | D86: 2000000 | E86: 1.0082075 | F86: =D86*E86 -> 2016415 | G86: 6000000000 | H86: 0
A87: 85 | B87: Kitchener | C87: R | D87: 2000000 | E87: 1.0126383 | F87: =D87*E87 -> 2025276.7 | G87: 6000000000 | H87: 0
A88: 86 | B88: Windsor | C88: R | D88: 2000000 | E88: 1.0109401 | F88: =D88*E88 -> 2021880.1 | G88: 6000000000 | H88: 0
A89: 87 | B89: Oakville | C89: R | D89: 2000000 | E89: 1.0273074 | F89: =D89*E89 -> 2054614.9 | G89: 6000000000 | H89: 0
A90: 88 | B90: Richmond Hill | C90: R | D90: 2000000 | E90: 1.0178776 | F90: =D90*E90 -> 2035755.2 | G90: 6000000000 | H90: 0
... A179: 177 | B179: Penetanguishene | C179: R | D179: 2000000 | E179: 1.0082075 | F179: =D179*E179 -> 2016415 | G179: 6000000000 | H179: 0
A180: 178 | B180: Fiat Chrysler Automobiles, Brampton Assembly Plant | C180: M | I180: =SUM(AE2:AE78)*0.8/18 -> 7153506.9 | J180: =SUM(AF2:AF78)*0.8/18 -> 7152503.8 | K180: =SUM(AG2:AG78)*0.8/18 -> 7152951.4 | L180: =SUM(AH2:AH78)*0.8/18 -> 7152957.4 | M180: =SUM(AI2:AI78)*0.8/18 -> 7152966.8 | N180: =SUM(AJ2:AJ78)*0.8/18 -> 7153394.5 | O180: =SUM(AK2:AK78)*0.8/18 -> 7153024 | P180: =SUM(AL2:AL78)*0.8/18 -> 7152872.6 | ... AB180: =SUM(AX2:AX78)*0.8/18 -> 7152830.6
A181: 179 | B181: Stellantis (Chrysler) Windsor | C181: M | I181: 7153506.9 | J181: 7152503.8 | K181: 7152951.4 | L181: 7152957.4 | M181: 7152966.8 | N181: 7153394.5 | O181: 7153024 | P181: 7152872.6 | Q181: 7153276.1 | R181: 7153372.6 | S181: 7152931.2 | T181: 7153332.4 | U181: 7153110.9 | V181: 7152918.5 | W181: 7152873.9 | X181: 7153068.2 | Y181: 7152769.6 | Z181: 7153040.2 | AA181: 7153141.6 | AB181: 7152830.6
A182: 180 | B182: Oakville Assembly Complex, Ford Motor Company of Canada, Limited | C182: M | I182: 7153506.9 | J182: 7152503.8 | K182: 7152951.4 | L182: 7152957.4 | M182: 7152966.8 | N182: 7153394.5 | O182: 7153024 | P182: 7152872.6 | Q182: 7153276.1 | R182: 7153372.6 | S182: 7152931.2 | T182: 7153332.4 | U182: 7153110.9 | V182: 7152918.5 | W182: 7152873.9 | X182: 7153068.2 | Y182: 7152769.6 | Z182: 7153040.2 | AA182: 7153141.6 | AB182: 7152830.6
A183: 181 | B183: St. Thomas Assembly Plant | C183: M | I183: 7153506.9 | J183: 7152503.8 | K183: 7152951.4 | L183: 7152957.4 | M183: 7152966.8 | N183: 7153394.5 | O183: 7153024 | P183: 7152872.6 | Q183: 7153276.1 | R183: 7153372.6 | S183: 7152931.2 | T183: 7153332.4 | U183: 7153110.9 | V183: 7152918.5 | W183: 7152873.9 | X183: 7153068.2 | Y183: 7152769.6 | Z183: 7153040.2 | AA183: 7153141.6 | AB183: 7152830.6
A184: 182 | B184: Ford Motor Co. Windsor Engine Plant | C184: M | I184: 7153506.9 | J184: 7152503.8 | K184: 7152951.4 | L184: 7152957.4 | M184: 7152966.8 | N184: 7153394.5 | O184: 7153024 | P184: 7152872.6 | Q184: 7153276.1 | R184: 7153372.6 | S184: 7152931.2 | T184: 7153332.4 | U184: 7153110.9 | V184: 7152918.5 | W184: 7152873.9 | X184: 7153068.2 | Y184: 7152769.6 | Z184: 7153040.2 | AA184: 7153141.6 | AB184: 7152830.6
A185: 183 | B185: Ford | C185: M | I185: 7153506.9 | J185: 7152503.8 | K185: 7152951.4 | L185: 7152957.4 | M185: 7152966.8 | N185: 7153394.5 | O185: 7153024 | P185: 7152872.6 | Q185: 7153276.1 | R185: 7153372.6 | S185: 7152931.2 | T185: 7153332.4 | U185: 7153110.9 | V185: 7152918.5 | W185: 7152873.9 | X185: 7153068.2 | Y185: 7152769.6 | Z185: 7153040.2 | AA185: 7153141.6 | AB185: 7152830.6
A186: 184 | B186: Oakville Assembly Complex, Ford Motor Company of Canada, Limited | C186: M | I186: 7153506.9 | J186: 7152503.8 | K186: 7152951.4 | L186: 7152957.4 | M186: 7152966.8 | N186: 7153394.5 | O186: 7153024 | P186: 7152872.6 | Q186: 7153276.1 | R186: 7153372.6 | S186: 7152931.2 | T186: 7153332.4 | U186: 7153110.9 | V186: 7152918.5 | W186: 7152873.9 | X186: 7153068.2 | Y186: 7152769.6 | Z186: 7153040.2 | AA186: 7153141.6 | AB186: 7152830.6
A187: 185 | B187: Ford Motor Co of Canada Ltd | C187: M | I187: 7153506.9 | J187: 7152503.8 | K187: 7152951.4 | L187: 7152957.4 | M187: 7152966.8 | N187: 7153394.5 | O187: 7153024 | P187: 7152872.6 | Q187: 7153276.1 | R187: 7153372.6 | S187: 7152931.2 | T187: 7153332.4 | U187: 7153110.9 | V187: 7152918.5 | W187: 7152873.9 | X187: 7153068.2 | Y187: 7152769.6 | Z187: 7153040.2 | AA187: 7153141.6 | AB187: 7152830.6
A188: 186 | B188: GM Oshawa Assembly | C188: M | I188: 7153506.9 | J188: 7152503.8 | K188: 7152951.4 | L188: 7152957.4 | M188: 7152966.8 | N188: 7153394.5 | O188: 7153024 | P188: 7152872.6 | Q188: 7153276.1 | R188: 7153372.6 | S188: 7152931.2 | T188: 7153332.4 | U188: 7153110.9 | V188: 7152918.5 | W188: 7152873.9 | X188: 7153068.2 | Y188: 7152769.6 | Z188: 7153040.2 | AA188: 7153141.6 | AB188: 7152830.6
A189: 187 | B189: General Motors of Canada Company | C189: M | I189: 7153506.9 | J189: 7152503.8 | K189: 7152951.4 | L189: 7152957.4 | M189: 7152966.8 | N189: 7153394.5 | O189: 7153024 | P189: 7152872.6 | Q189: 7153276.1 | R189: 7153372.6 | S189: 7152931.2 | T189: 7153332.4 | U189: 7153110.9 | V189: 7152918.5 | W189: 7152873.9 | X189: 7153068.2 | Y189: 7152769.6 | Z189: 7153040.2 | AA189: 7153141.6 | AB189: 7152830.6
A190: 188 | B190: GM CAMI Assembly | C190: M | I190: 7153506.9 | J190: 7152503.8 | K190: 7152951.4 | L190: 7152957.4 | M190: 7152966.8 | N190: 7153394.5 | O190: 7153024 | P190: 7152872.6 | Q190: 7153276.1 | R190: 7153372.6 | S190: 7152931.2 | T190: 7153332.4 | U190: 7153110.9 | V190: 7152918.5 | W190: 7152873.9 | X190: 7153068.2 | Y190: 7152769.6 | Z190: 7153040.2 | AA190: 7153141.6 | AB190: 7152830.6
A191: 189 | B191: Honda of Canada Mfg. | C191: M | I191: 7153506.9 | J191: 7152503.8 | K191: 7152951.4 | L191: 7152957.4 | M191: 7152966.8 | N191: 7153394.5 | O191: 7153024 | P191: 7152872.6 | Q191: 7153276.1 | R191: 7153372.6 | S191: 7152931.2 | T191: 7153332.4 | U191: 7153110.9 | V191: 7152918.5 | W191: 7152873.9 | X191: 7153068.2 | Y191: 7152769.6 | Z191: 7153040.2 | AA191: 7153141.6 | AB191: 7152830.6
A192: 190 | B192: Honda of Canada Manufacturing Gate B Rafid | C192: M | I192: 7153506.9 | J192: 7152503.8 | K192: 7152951.4 | L192: 7152957.4 | M192: 7152966.8 | N192: 7153394.5 | O192: 7153024 | P192: 7152872.6 | Q192: 7153276.1 | R192: 7153372.6 | S192: 7152931.2 | T192: 7153332.4 | U192: 7153110.9 | V192: 7152918.5 | W192: 7152873.9 | X192: 7153068.2 | Y192: 7152769.6 | Z192: 7153040.2 | AA192: 7153141.6 | AB192: 7152830.6
...

Sheet Node_stochastic_20
A1: nodeNum | B1: City | C1: type | D1: f_i | E1: capacity | F1: o_i | G1: d_1 | H1: d_2 | I1: d_3 | J1: d_4 | K1: d_5 | L1: d_6 | M1: d_7 | N1: d_8 | O1: d_9 | P1: d_10 | Q1: d_11 | R1: d_12 | S1: d_13 | T1: d_14 | U1: d_15 | V1: d_16 | W1: d_17 | X1: d_18 | Y1: d_19 | Z1: d_20 | AA1: si | AB1: si_num | AC1: s_1 | AD1: s_2 | AE1: s_3 | AF1: s_4 | AG1: s_5 | AH1: s_6 | AI1: s_7 | AJ1: s_8 | AK1: s_9 | AL1: s_10 | AM1: s_11 | AN1: s_12 | AO1: s_13 | AP1: s_14 | AQ1: s_15 | AR1: s_16 | AS1: s_17 | AT1: s_18 | AU1: s_19 | AV1: s_20 | AW1: s_21 | AX1: s_22
A2: 0 | B2: Acton | C2: C | AA2: 52750 | AB2: =AA2*25 -> 1318750 | AC2: 1269840.6 | AD2: 1177060.3 | AE2: 1364375.8 | AF2: 1729294.9 | AG2: 1862210.7 | AH2: 1652842 | AI2: 1464194.1 | AJ2: 982944.66 | AK2: 1301630.8 | AL2: 1321113.2 | AM2: 1184386.9 | AN2: 1370347.6 | AO2: 1461086.9 | AP2: 1101303.8 | AQ2: 1275831.7 | AR2: 1262423.1 | AS2: 1063818.7 | AT2: 1504088.6 | AU2: 1147469.1 | AV2: 1374870.8 | AW2: 1558216.8 | AX2: 1281276.4
A3: 1 | B3: Arnprior | C3: C | AA3: 29860 | AB3: =AA3*25 -> 746500 | AC3: 615710.05 | AD3: 700197.36 | AE3: 759369.02 | AF3: 590112.78 | AG3: 775812.48 | AH3: 684640.84 | AI3: 583457.39 | AJ3: 431642.15 | AK3: 1006804.2 | AL3: 540506.41 | AM3: 430401.16 | AN3: 636022.62 | AO3: 689224.4 | AP3: 443978.37 | AQ3: 680554.58 | AR3: 731764.17 | AS3: 924805.89 | AT3: 847956.98 | AU3: 1003388.5 | AV3: 945949.95 | AW3: 786158.24 | AX3: 846680.65
A4: 2 | B4: Arthur | C4: C | AA4: 44602 | AB4: =AA4*25 -> 1115050 | AC4: 1155619.6 | AD4: 855278.92 | AE4: 1114511.4 | AF4: 856741.53 | AG4: 1300672.9 | AH4: 1083474.8 | AI4: 1118919.4 | AJ4: 854660.78 | AK4: 982392.6 | AL4: 813217.09 | AM4: 1015950.3 | AN4: 1542009.6 | AO4: 1019546.7 | AP4: 834918.58 | AQ4: 1088906.6 | AR4: 1003082.9 | AS4: 1149702.7 | AT4: 1007237.7 | AU4: 1113345.5 | AV4: 828560.16 | AW4: 759357.94 | AX4: 802528.87
A5: 3 | B5: Aurora | C5: C | AA5: 110396 | AB5: =AA5*25 -> 2759900 | AC5: 3499337 | AD5: 3741927.1 | AE5: 2243204.5 | AF5: 2452510.2 | AG5: 3366783.8 | AH5: 2356057.8 | AI5: 3228949.3 | AJ5: 1671923.1 | AK5: 3197448.7 | AL5: 3560418 | AM5: 2208418.5 | AN5: 3126952.7 | AO5: 3092226.1 | AP5: 3437440.8 | AQ5: 3215750 | AR5: 3725420.2 | AS5: 3214201.2 | AT5: 2648891.6 | AU5: 3225103.5 | AV5: 3296806.2 | AW5: 3289433 | AX5: 2961411.3
A6: 4 | B6: Beaverton | C6: C | AA6: 77661 | AB6: =AA6*25 -> 1941525 | AC6: 1340075.7 | AD6: 2128663.2 | AE6: 1754262.8 | AF6: 1878757.6 | AG6: 2054225.6 | AH6: 1315197.9 | AI6: 1372249.5 | AJ6: 1825783.6 | AK6: 1855393.3 | AL6: 2123128.6 | AM6: 1773068.6 | AN6: 2192716 | AO6: 1282234.6 | AP6: 1927113.5 | AQ6: 1758586.9 | AR6: 1764954.7 | AS6: 2416564.1 | AT6: 2876353.8 | AU6: 1369547.9 | AV6: 1627867.5 | AW6: 2288428 | AX6: 1787420
A7: 5 | B7: Bowmanville | C7: C | AA7: 77661 | AB7: =AA7*25 -> 1941525 | AC7: 1647478.4 | AD7: 1700425.9 | AE7: 1659199.5 | AF7: 2025655.1 | AG7: 2151331.1 | AH7: 1269115.2 | AI7: 2119200 | AJ7: 2038642.2 | AK7: 1809305.7 | AL7: 1635101.8 | AM7: 1889039.7 | AN7: 2266752.8 | AO7: 1714418.1 | AP7: 2201901.9 | AQ7: 2267379.9 | AR7: 1907735.7 | AS7: 2186043.9 | AT7: 1455226.7 | AU7: 2106309.1 | AV7: 1721600.5 | AW7: 1009223.8 | AX7: 1014787.5
A8: 6 | B8: Bradford | C8: C | AA8: 103343 | AB8: =AA8*25 -> 2583575 | AC8: 3058405.1 | AD8: 3206334.9 | AE8: 3213215 | AF8: 3458330.4 | AG8: 2505553.6 | AH8: 3147918.6 | AI8: 2455606.1 | AJ8: 2416776.3 | AK8: 3464456.9 | AL8: 2642846.2 | AM8: 2681598 | AN8: 2199117.6 | AO8: 3972662.9 | AP8: 2566249.2 | AQ8: 2433718.1 | AR8: 3030854.9 | AS8: 2211172.9 | AT8: 2464277.2 | AU8: 3080606.6 | AV8: 2384566 | AW8: 2315977.3 | AX8: 2700461.1
A9: 7 | B9: Brampton | C9: C | AA9: 371033 | AB9: =AA9*25 -> 9275825 | AC9: 13906052 | AD9: 10616621 | AE9: 6429251.3 | AF9: 10769159 | AG9: 7505899.7 | AH9: 11006175 | AI9: 12132414 | AJ9: 8636450.2 | AK9: 5454213.8 | AL9: 10132208 | AM9: 9409651.8 | AN9: 7513806.8 | AO9: 10360106 | AP9: 9290069.2 | AQ9: 10607793 | AR9: 9105089.7 | AS9: 8683918.9 | AT9: 8876343.1 | AU9: 6061122.2 | AV9: 11474143 | AW9: 8519939.3 | AX9: 11021065
A10: 8 | B10: Brantford | C10: C | AA10: 83809 | AB10: =AA10*25 -> 2095225 | AC10: 2162166.1 | AD10: 1741284.3 | AE10: 2647891.3 | AF10: 2158384.2 | AG10: 2107107.3 | AH10: 1836974.8 | AI10: 2377344.9 | AJ10: 2272384.9 | AK10: 1827638 | AL10: 1994430.1 | AM10: 2384009.6 | AN10: 3017920.6 | AO10: 2573783.6 | AP10: 1767019.5 | AQ10: 2035281.3 | AR10: 2682157.9 | AS10: 2129809.9 | AT10: 1854030.7 | AU10: 2389532.2 | AV10: 2549885.8 | AW10: 2328652.8 | AX10: 1287232.7
A11: 9 | B11: Caistor Centre | C11: C | AA11: 4704 | AB11: =AA11*25 -> 117600 | AC11: 109115.17 | AD11: 145475.18 | AE11: 96270.113 | AF11: 88653.837 | AG11: 161000.62 | AH11: 150667.37 | AI11: 117852.31 | AJ11: 106642.62 | AK11: 140498.66 | AL11: 139771.4 | AM11: 98136.72 | AN11: 93173.519 | AO11: 133213.2 | AP11: 131227.67 | AQ11: 126697.07 | AR11: 110671.82 | AS11: 131499.04 | AT11: 107520.46 | AU11: 145574.59 | AV11: 137570.38 | AW11: 174620.05 | AX11: 127915.87
A12: 10 | B12: Caledon | C12: C | AA12: 371033 | AB12: =AA12*25 -> 9275825 | AC12: 9467372.6 | AD12: 9926844.5 | AE12: 10877611 | AF12: 7548335.6 | AG12: 9583021.5 | AH12: 8635926.3 | AI12: 7426783.4 | AJ12: 9336493.4 | AK12: 10293779 | AL12: 11709073 | AM12: 7596948 | AN12: 9059931.3 | AO12: 8978929.3 | AP12: 7373577.9 | AQ12: 9714171.8 | AR12: 8255278.3 | AS12: 8401689.1 | AT12: 5895127.1 | AU12: 4704827.8 | AV12: 8605112.7 | AW12: 11774767 | AX12: 11233806
A13: 11 | B13: Cambridge | C13: C | AA13: 107823 | AB13: =AA13*25 -> 2695575 | AC13: 3509223.5 | AD13: 2994643.3 | AE13: 2237166.9 | AF13: 3583842.5 | AG13: 3247074.5 | AH13: 2167401.4 | AI13: 2596917.5 | AJ13: 2611060.5 | AK13: 3329754.6 | AL13: 2815303.3 | AM13: 2167453 | AN13: 2554794.9 | AO13: 3714119.5 | AP13: 1809500.9 | AQ13: 2343545 | AR13: 3046458.3 | AS13: 1962340.6 | AT13: 2926308.4 | AU13: 2388513.1 | AV13: 2781791 | AW13: 2629533.4 | AX13: 2560578.1
... A78: 76 | B78: Windsor | C78: C | AA78: 56665 | AB78: =AA78*25 -> 1416625 | AC78: 1292965.4 | AD78: 1560304.2 | AE78: 1689595.9 | AF78: 1124553.6 | AG78: 1684682.2 | AH78: 1329196.5 | AI78: 779928.11 | AJ78: 1267792.9 | AK78: 1028610.2 | AL78: 1013315 | AM78: 864547.47 | AN78: 1488248.1 | AO78: 1834969.5 | AP78: 1832119 | AQ78: 1895726.1 | AR78: 1375009.9 | AS78: 1094253.9 | AT78: 1274240.2 | AU78: 978497.56 | AV78: 1555283.3 | AW78: 1095734.8 | AX78: 1310709.8
A79: 77 | B79: Toronto | C79: R | D79: 2018592.8 | E79: 6000000000 | F79: 0.02
A80: 78 | B80: Ottawa | C80: R | D80: 2012544.2 | E80: 6000000000 | F80: 0.02
A81: 79 | B81: Mississauga | C81: R | D81: 2035869.4 | E81: 6000000000 | F81: 0.02
A82: 80 | B82: Brampton | C82: R | D82: 2035869.4 | E82: 6000000000 | F82: 0.02
A83: 81 | B83: Hamilton | C83: R | D83: 2035755.2 | E83: 6000000000 | F83: 0.02
A84: 82 | B84: London | C84: R | D84: 2019654.7 | E84: 6000000000 | F84: 0.02
A85: 83 | B85: Markham | C85: R | D85: 2035755.2 | E85: 6000000000 | F85: 0.02
A86: 84 | B86: Vaughan | C86: R | D86: 2016415 | E86: 6000000000 | F86: 0.02
A87: 85 | B87: Kitchener | C87: R | D87: 2025276.7 | E87: 6000000000 | F87: 0.02
A88: 86 | B88: Windsor | C88: R | D88: 2021880.1 | E88: 6000000000 | F88: 0.02
A89: 87 | B89: Oakville | C89: R | D89: 2054614.9 | E89: 6000000000 | F89: 0.02
A90: 88 | B90: Richmond Hill | C90: R | D90: 2035755.2 | E90: 6000000000 | F90: 0.02
... A179: 177 | B179: Penetanguishene | C179: R | D179: 2016415 | E179: 6000000000 | F179: 0.02
A180: 178 | B180: Fiat Chrysler Automobiles, Brampton Assembly Plant | C180: M | G180: =SUM(AC2:AC78)*0.8/18 -> 7376676.7 | H180: =SUM(AD2:AD78)*0.8/18 -> 7352967.5 | I180: =SUM(AE2:AE78)*0.8/18 -> 7656297.6 | J180: =SUM(AF2:AF78)*0.8/18 -> 7330817.8 | K180: =SUM(AG2:AG78)*0.8/18 -> 6989777.5 | L180: =SUM(AH2:AH78)*0.8/18 -> 7173195 | M180: =SUM(AI2:AI78)*0.8/18 -> 6919464.6 | N180: =SUM(AJ2:AJ78)*0.8/18 -> 7592003.6 | ... Z180: =SUM(AV2:AV78)*0.8/18 -> 6961000.6
A181: 179 | B181: Stellantis (Chrysler) Windsor | C181: M | G181: 7376676.7 | H181: 7352967.5 | I181: 7656297.6 | J181: 7330817.8 | K181: 6989777.5 | L181: 7173195 | M181: 6919464.6 | N181: 7592003.6 | O181: 7422361 | P181: 7318758.2 | Q181: 7334975.2 | R181: 6969189.8 | S181: 6851648.1 | T181: 6908924.1 | U181: 7284130.6 | V181: 7658655 | W181: 7232437.3 | X181: 6139432.4 | Y181: 6683787.2 | Z181: 6961000.6
A182: 180 | B182: Oakville Assembly Complex, Ford Motor Company of Canada, Limited | C182: M | G182: 7376676.7 | H182: 7352967.5 | I182: 7656297.6 | J182: 7330817.8 | K182: 6989777.5 | L182: 7173195 | M182: 6919464.6 | N182: 7592003.6 | O182: 7422361 | P182: 7318758.2 | Q182: 7334975.2 | R182: 6969189.8 | S182: 6851648.1 | T182: 6908924.1 | U182: 7284130.6 | V182: 7658655 | W182: 7232437.3 | X182: 6139432.4 | Y182: 6683787.2 | Z182: 6961000.6
A183: 181 | B183: St. Thomas Assembly Plant | C183: M | G183: 7376676.7 | H183: 7352967.5 | I183: 7656297.6 | J183: 7330817.8 | K183: 6989777.5 | L183: 7173195 | M183: 6919464.6 | N183: 7592003.6 | O183: 7422361 | P183: 7318758.2 | Q183: 7334975.2 | R183: 6969189.8 | S183: 6851648.1 | T183: 6908924.1 | U183: 7284130.6 | V183: 7658655 | W183: 7232437.3 | X183: 6139432.4 | Y183: 6683787.2 | Z183: 6961000.6
A184: 182 | B184: Ford Motor Co. Windsor Engine Plant | C184: M | G184: 7376676.7 | H184: 7352967.5 | I184: 7656297.6 | J184: 7330817.8 | K184: 6989777.5 | L184: 7173195 | M184: 6919464.6 | N184: 7592003.6 | O184: 7422361 | P184: 7318758.2 | Q184: 7334975.2 | R184: 6969189.8 | S184: 6851648.1 | T184: 6908924.1 | U184: 7284130.6 | V184: 7658655 | W184: 7232437.3 | X184: 6139432.4 | Y184: 6683787.2 | Z184: 6961000.6
A185: 183 | B185: Ford | C185: M | G185: 7376676.7 | H185: 7352967.5 | I185: 7656297.6 | J185: 7330817.8 | K185: 6989777.5 | L185: 7173195 | M185: 6919464.6 | N185: 7592003.6 | O185: 7422361 | P185: 7318758.2 | Q185: 7334975.2 | R185: 6969189.8 | S185: 6851648.1 | T185: 6908924.1 | U185: 7284130.6 | V185: 7658655 | W185: 7232437.3 | X185: 6139432.4 | Y185: 6683787.2 | Z185: 6961000.6
A186: 184 | B186: Oakville Assembly Complex, Ford Motor Company of Canada, Limited | C186: M | G186: 7376676.7 | H186: 7352967.5 | I186: 7656297.6 | J186: 7330817.8 | K186: 6989777.5 | L186: 7173195 | M186: 6919464.6 | N186: 7592003.6 | O186: 7422361 | P186: 7318758.2 | Q186: 7334975.2 | R186: 6969189.8 | S186: 6851648.1 | T186: 6908924.1 | U186: 7284130.6 | V186: 7658655 | W186: 7232437.3 | X186: 6139432.4 | Y186: 6683787.2 | Z186: 6961000.6
A187: 185 | B187: Ford Motor Co of Canada Ltd | C187: M | G187: 7376676.7 | H187: 7352967.5 | I187: 7656297.6 | J187: 7330817.8 | K187: 6989777.5 | L187: 7173195 | M187: 6919464.6 | N187: 7592003.6 | O187: 7422361 | P187: 7318758.2 | Q187: 7334975.2 | R187: 6969189.8 | S187: 6851648.1 | T187: 6908924.1 | U187: 7284130.6 | V187: 7658655 | W187: 7232437.3 | X187: 6139432.4 | Y187: 6683787.2 | Z187: 6961000.6
A188: 186 | B188: GM Oshawa Assembly | C188: M | G188: 7376676.7 | H188: 7352967.5 | I188: 7656297.6 | J188: 7330817.8 | K188: 6989777.5 | L188: 7173195 | M188: 6919464.6 | N188: 7592003.6 | O188: 7422361 | P188: 7318758.2 | Q188: 7334975.2 | R188: 6969189.8 | S188: 6851648.1 | T188: 6908924.1 | U188: 7284130.6 | V188: 7658655 | W188: 7232437.3 | X188: 6139432.4 | Y188: 6683787.2 | Z188: 6961000.6
A189: 187 | B189: General Motors of Canada Company | C189: M | G189: 7376676.7 | H189: 7352967.5 | I189: 7656297.6 | J189: 7330817.8 | K189: 6989777.5 | L189: 7173195 | M189: 6919464.6 | N189: 7592003.6 | O189: 7422361 | P189: 7318758.2 | Q189: 7334975.2 | R189: 6969189.8 | S189: 6851648.1 | T189: 6908924.1 | U189: 7284130.6 | V189: 7658655 | W189: 7232437.3 | X189: 6139432.4 | Y189: 6683787.2 | Z189: 6961000.6
A190: 188 | B190: GM CAMI Assembly | C190: M | G190: 7376676.7 | H190: 7352967.5 | I190: 7656297.6 | J190: 7330817.8 | K190: 6989777.5 | L190: 7173195 | M190: 6919464.6 | N190: 7592003.6 | O190: 7422361 | P190: 7318758.2 | Q190: 7334975.2 | R190: 6969189.8 | S190: 6851648.1 | T190: 6908924.1 | U190: 7284130.6 | V190: 7658655 | W190: 7232437.3 | X190: 6139432.4 | Y190: 6683787.2 | Z190: 6961000.6
A191: 189 | B191: Honda of Canada Mfg. | C191: M | G191: 7376676.7 | H191: 7352967.5 | I191: 7656297.6 | J191: 7330817.8 | K191: 6989777.5 | L191: 7173195 | M191: 6919464.6 | N191: 7592003.6 | O191: 7422361 | P191: 7318758.2 | Q191: 7334975.2 | R191: 6969189.8 | S191: 6851648.1 | T191: 6908924.1 | U191: 7284130.6 | V191: 7658655 | W191: 7232437.3 | X191: 6139432.4 | Y191: 6683787.2 | Z191: 6961000.6
A192: 190 | B192: Honda of Canada Manufacturing Gate B Rafid | C192: M | G192: 7376676.7 | H192: 7352967.5 | I192: 7656297.6 | J192: 7330817.8 | K192: 6989777.5 | L192: 7173195 | M192: 6919464.6 | N192: 7592003.6 | O192: 7422361 | P192: 7318758.2 | Q192: 7334975.2 | R192: 6969189.8 | S192: 6851648.1 | T192: 6908924.1 | U192: 7284130.6 | V192: 7658655 | W192: 7232437.3 | X192: 6139432.4 | Y192: 6683787.2 | Z192: 6961000.6
...

Sheet Node_stochastic_30
A1: nodeNum | B1: City | C1: type | D1: f_i | E1: capacity | F1: o_i | G1: d_1 | H1: d_2 | I1: d_3 | J1: d_4 | K1: d_5 | L1: d_6 | M1: d_7 | N1: d_8 | O1: d_9 | P1: d_10 | Q1: d_11 | R1: d_12 | S1: d_13 | T1: d_14 | U1: d_15 | V1: d_16 | W1: d_17 | X1: d_18 | Y1: d_19 | Z1: d_20 | AA1: si | AB1: si_num | AC1: s_1 | AD1: s_2 | AE1: s_3 | AF1: s_4 | AG1: s_5 | AH1: s_6 | AI1: s_7 | AJ1: s_8 | AK1: s_9 | AL1: s_10 | AM1: s_11 | AN1: s_12 | AO1: s_13 | AP1: s_14 | AQ1: s_15 | AR1: s_16 | AS1: s_17 | AT1: s_18 | AU1: s_19 | AV1: s_20 | AW1: s_21 | AX1: s_22
A2: 0 | B2: Acton | C2: C | AA2: 52750 | AB2: =AA2*25 -> 1318750 | AC2: 1423961.7 | AD2: 837044.74 | AE2: 976922.49 | AF2: 1123718 | AG2: 1758022.2 | AH2: 1136282.6 | AI2: 612315.9 | AJ2: 1368383.9 | AK2: 1133658.5 | AL2: 1235991.4 | AM2: 938410.41 | AN2: 1363904.2 | AO2: 1063221.9 | AP2: 1193125.5 | AQ2: 1183987.9 | AR2: 1266791.1 | AS2: 996550.43 | AT2: 1309276.3 | AU2: 925502.69 | AV2: 1156688.3 | AW2: 811006.19 | AX2: 1238136.1
A3: 1 | B3: Arnprior | C3: C | AA3: 29860 | AB3: =AA3*25 -> 746500 | AC3: 1051496.4 | AD3: 588500.25 | AE3: 508793.01 | AF3: 741754.21 | AG3: 1189702.6 | AH3: 856269.3 | AI3: 572402.81 | AJ3: 572854.67 | AK3: 682369.68 | AL3: 418685.54 | AM3: 601110.81 | AN3: 626890.75 | AO3: 877924.62 | AP3: 651953.26 | AQ3: 773931.71 | AR3: 839701.49 | AS3: 945952.67 | AT3: 332984.02 | AU3: 609744.88 | AV3: 834957.37 | AW3: 440510.24 | AX3: 736868.01
A4: 2 | B4: Arthur | C4: C | AA4: 44602 | AB4: =AA4*25 -> 1115050 | AC4: 1512907.5 | AD4: 620208.34 | AE4: 1130228.7 | AF4: 1431588.4 | AG4: 592008 | AH4: 693483.04 | AI4: 874417.88 | AJ4: 589068.65 | AK4: 642463.1 | AL4: 1466744.8 | AM4: 881557.12 | AN4: 859393.37 | AO4: 853996.17 | AP4: 1476722.8 | AQ4: 1637203.7 | AR4: 683769.38 | AS4: 996922.62 | AT4: 841971.51 | AU4: 721171.08 | AV4: 1168491.4 | AW4: 1034978.5 | AX4: 1296402.8
A5: 3 | B5: Aurora | C5: C | AA5: 110396 | AB5: =AA5*25 -> 2759900 | AC5: 3331796.4 | AD5: 1491457.3 | AE5: 2697876.3 | AF5: 3700345.9 | AG5: 2317187.9 | AH5: 3529002.7 | AI5: 2942364.3 | AJ5: 596557.5 | AK5: 3170955 | AL5: 3114796 | AM5: 2779568.4 | AN5: 1331762.9 | AO5: 1751940.2 | AP5: 3513214.6 | AQ5: 2529462.7 | AR5: 3141884.2 | AS5: 837618.45 | AT5: 2719148.1 | AU5: 2623147.8 | AV5: 4585604.4 | AW5: 3448792.5 | AX5: 2087053.9
A6: 4 | B6: Beaverton | C6: C | AA6: 77661 | AB6: =AA6*25 -> 1941525 | AC6: 2727286.9 | AD6: 1484058.8 | AE6: 2111040.6 | AF6: 1998465.6 | AG6: 2428673.1 | AH6: 1491095.1 | AI6: 1888123.6 | AJ6: 1614749.8 | AK6: 1713184.1 | AL6: 1998193.8 | AM6: 2121631.4 | AN6: 1913171.3 | AO6: 2340259.7 | AP6: 1911857.2 | AQ6: 1310146 | AR6: 3012098.4 | AS6: 1688919.5 | AT6: 2445238.2 | AU6: 1048717.9 | AV6: 2671527.8 | AW6: 1910905.5 | AX6: 2725857.3
A7: 5 | B7: Bowmanville | C7: C | AA7: 77661 | AB7: =AA7*25 -> 1941525 | AC7: 1507132.1 | AD7: 1440514 | AE7: 2188885.7 | AF7: 2156295.3 | AG7: 791928.98 | AH7: 1949585.3 | AI7: 2288676.5 | AJ7: 635185.67 | AK7: 2719282.6 | AL7: 1945922.9 | AM7: 1633049.5 | AN7: 2318410.3 | AO7: 1176802 | AP7: 2658160.1 | AQ7: 1297029.9 | AR7: 2019697.6 | AS7: 1648131.4 | AT7: 2627879.8 | AU7: 850172.88 | AV7: 2018085.2 | AW7: 1681888 | AX7: 2938133.6
A8: 6 | B8: Bradford | C8: C | AA8: 103343 | AB8: =AA8*25 -> 2583575 | AC8: 2336106.4 | AD8: 2337379.6 | AE8: 2873934.5 | AF8: 2608145.5 | AG8: 774029.47 | AH8: 3188674.4 | AI8: 2900297.6 | AJ8: 724045 | AK8: 2037133.8 | AL8: 1924166.6 | AM8: 1168947.7 | AN8: 2832291.3 | AO8: 3281993.4 | AP8: 3133807.5 | AQ8: 2471401.5 | AR8: 2090832.4 | AS8: 2424038.4 | AT8: 1504518.7 | AU8: 3101501 | AV8: 1608037.4 | AW8: 2754524.8 | AX8: 2430385.7
A9: 7 | B9: Brampton | C9: C | AA9: 371033 | AB9: =AA9*25 -> 9275825 | AC9: 13368141 | AD9: 10877195 | AE9: 9667382.4 | AF9: 8661457.1 | AG9: 10596013 | AH9: 12436133 | AI9: 8660224.5 | AJ9: 10651631 | AK9: 11247063 | AL9: 2844850.1 | AM9: 11443055 | AN9: 8249381.9 | AO9: 16873486 | AP9: 10881696 | AQ9: 10911707 | AR9: 8529929.6 | AS9: 6686161.4 | AT9: 5951791.4 | AU9: 11839185 | AV9: 7672587.4 | AW9: 13884644 | AX9: 10777370
A10: 8 | B10: Brantford | C10: C | AA10: 83809 | AB10: =AA10*25 -> 2095225 | AC10: 2497385.8 | AD10: 1908824.4 | AE10: 1955029.9 | AF10: 2151884.4 | AG10: 2183996.9 | AH10: 920824.69 | AI10: 2985790.8 | AJ10: 2472831.2 | AK10: 923302.05 | AL10: 2096879.6 | AM10: 2447387.7 | AN10: 2474205.6 | AO10: 2102737 | AP10: 2048395.5 | AQ10: 2329429.6 | AR10: 1109331.5 | AS10: 1916610.9 | AT10: 1801124.2 | AU10: 1905359.1 | AV10: 2454648.7 | AW10: 1011123.4 | AX10: 2719266.5
A11: 9 | B11: Caistor Centre | C11: C | AA11: 4704 | AB11: =AA11*25 -> 117600 | AC11: 140520.21 | AD11: 148877.73 | AE11: 168227.24 | AF11: 135616.32 | AG11: 139874.21 | AH11: 198315.21 | AI11: 75006.21 | AJ11: 125297.67 | AK11: 166880.44 | AL11: 161378.82 | AM11: 127372.8 | AN11: 88822.268 | AO11: 142173.91 | AP11: 158294.37 | AQ11: 174462.84 | AR11: 240224.26 | AS11: 204235.26 | AT11: 131233.12 | AU11: 143668.52 | AV11: 115735.63 | AW11: 204214.61 | AX11: 125890.14
A12: 10 | B12: Caledon | C12: C | AA12: 371033 | AB12: =AA12*25 -> 9275825 | AC12: 9956229.8 | AD12: 12958530 | AE12: 7877130.2 | AF12: 3986536.5 | AG12: 9224920.3 | AH12: 8450336.1 | AI12: 5664818.3 | AJ12: 10031691 | AK12: 7483165.7 | AL12: 2604842.7 | AM12: 10902563 | AN12: 10077983 | AO12: 11282347 | AP12: 10796425 | AQ12: 7851676.7 | AR12: 8820575.9 | AS12: 3392746.7 | AT12: 14808824 | AU12: 8256734.1 | AV12: 12605150 | AW12: 9434542 | AX12: 7002258.1
A13: 11 | B13: Cambridge | C13: C | AA13: 107823 | AB13: =AA13*25 -> 2695575 | AC13: 2235907.7 | AD13: 3118574.6 | AE13: 1530563.8 | AF13: 3308288.9 | AG13: 2090917.1 | AH13: 2140352.8 | AI13: 2246624.5 | AJ13: 659316.44 | AK13: 3390790.7 | AL13: 3281973.7 | AM13: 3597915 | AN13: 4148248.3 | AO13: 3691434 | AP13: 1246119.6 | AQ13: 1899998.7 | AR13: 3308684.6 | AS13: 2776043.9 | AT13: 2690891.2 | AU13: 1578863.4 | AV13: 2864266.4 | AW13: 3060949.3 | AX13: 3891303.8
... A78: 76 | B78: Windsor | C78: C | AA78: 56665 | AB78: =AA78*25 -> 1416625 | AC78: 1426956.9 | AD78: 1897369.4 | AE78: 1695022.8 | AF78: 1671068 | AG78: 1509330.6 | AH78: 818672.36 | AI78: 1702246.6 | AJ78: 1851820.1 | AK78: 1338580.2 | AL78: 1191092.8 | AM78: 1227110.7 | AN78: 1081198.5 | AO78: 1036054.8 | AP78: 1338249.1 | AQ78: 1888283.6 | AR78: 1224294.4 | AS78: 824331.3 | AT78: 832971.12 | AU78: 1211888.8 | AV78: 1161812.4 | AW78: 1590106 | AX78: 1590135.1
A79: 77 | B79: Toronto | C79: R | D79: 2018592.8 | E79: 6000000000 | F79: 0.02
A80: 78 | B80: Ottawa | C80: R | D80: 2012544.2 | E80: 6000000000 | F80: 0.02
A81: 79 | B81: Mississauga | C81: R | D81: 2035869.4 | E81: 6000000000 | F81: 0.02
A82: 80 | B82: Brampton | C82: R | D82: 2035869.4 | E82: 6000000000 | F82: 0.02
A83: 81 | B83: Hamilton | C83: R | D83: 2035755.2 | E83: 6000000000 | F83: 0.02
A84: 82 | B84: London | C84: R | D84: 2019654.7 | E84: 6000000000 | F84: 0.02
A85: 83 | B85: Markham | C85: R | D85: 2035755.2 | E85: 6000000000 | F85: 0.02
A86: 84 | B86: Vaughan | C86: R | D86: 2016415 | E86: 6000000000 | F86: 0.02
A87: 85 | B87: Kitchener | C87: R | D87: 2025276.7 | E87: 6000000000 | F87: 0.02
A88: 86 | B88: Windsor | C88: R | D88: 2021880.1 | E88: 6000000000 | F88: 0.02
A89: 87 | B89: Oakville | C89: R | D89: 2054614.9 | E89: 6000000000 | F89: 0.02
A90: 88 | B90: Richmond Hill | C90: R | D90: 2035755.2 | E90: 6000000000 | F90: 0.02
... A179: 177 | B179: Penetanguishene | C179: R | D179: 2016415 | E179: 6000000000 | F179: 0.02
A180: 178 | B180: Fiat Chrysler Automobiles, Brampton Assembly Plant | C180: M | G180: =SUM(AC2:AC78)*0.8/18 -> 7666974.2 | H180: =SUM(AD2:AD78)*0.8/18 -> 6982670.2 | I180: =SUM(AE2:AE78)*0.8/18 -> 6640095.9 | J180: =SUM(AF2:AF78)*0.8/18 -> 6194497.9 | K180: =SUM(AG2:AG78)*0.8/18 -> 6609785.9 | L180: =SUM(AH2:AH78)*0.8/18 -> 7396983.9 | M180: =SUM(AI2:AI78)*0.8/18 -> 7378626.3 | N180: =SUM(AJ2:AJ78)*0.8/18 -> 8066369.5 | ... Z180: =SUM(AV2:AV78)*0.8/18 -> 7044135.1
A181: 179 | B181: Stellantis (Chrysler) Windsor | C181: M | G181: 7666974.2 | H181: 6982670.2 | I181: 6640095.9 | J181: 6194497.9 | K181: 6609785.9 | L181: 7396983.9 | M181: 7378626.3 | N181: 8066369.5 | O181: 7376221.8 | P181: 6786824.3 | Q181: 7521165 | R181: 7502118.1 | S181: 7172332.7 | T181: 7109735.9 | U181: 7144174.6 | V181: 6485981.8 | W181: 6920206.7 | X181: 7612664.3 | Y181: 7332747.7 | Z181: 7044135.1
A182: 180 | B182: Oakville Assembly Complex, Ford Motor Company of Canada, Limited | C182: M | G182: 7666974.2 | H182: 6982670.2 | I182: 6640095.9 | J182: 6194497.9 | K182: 6609785.9 | L182: 7396983.9 | M182: 7378626.3 | N182: 8066369.5 | O182: 7376221.8 | P182: 6786824.3 | Q182: 7521165 | R182: 7502118.1 | S182: 7172332.7 | T182: 7109735.9 | U182: 7144174.6 | V182: 6485981.8 | W182: 6920206.7 | X182: 7612664.3 | Y182: 7332747.7 | Z182: 7044135.1
A183: 181 | B183: St. Thomas Assembly Plant | C183: M | G183: 7666974.2 | H183: 6982670.2 | I183: 6640095.9 | J183: 6194497.9 | K183: 6609785.9 | L183: 7396983.9 | M183: 7378626.3 | N183: 8066369.5 | O183: 7376221.8 | P183: 6786824.3 | Q183: 7521165 | R183: 7502118.1 | S183: 7172332.7 | T183: 7109735.9 | U183: 7144174.6 | V183: 6485981.8 | W183: 6920206.7 | X183: 7612664.3 | Y183: 7332747.7 | Z183: 7044135.1
A184: 182 | B184: Ford Motor Co. Windsor Engine Plant | C184: M | G184: 7666974.2 | H184: 6982670.2 | I184: 6640095.9 | J184: 6194497.9 | K184: 6609785.9 | L184: 7396983.9 | M184: 7378626.3 | N184: 8066369.5 | O184: 7376221.8 | P184: 6786824.3 | Q184: 7521165 | R184: 7502118.1 | S184: 7172332.7 | T184: 7109735.9 | U184: 7144174.6 | V184: 6485981.8 | W184: 6920206.7 | X184: 7612664.3 | Y184: 7332747.7 | Z184: 7044135.1
A185: 183 | B185: Ford | C185: M | G185: 7666974.2 | H185: 6982670.2 | I185: 6640095.9 | J185: 6194497.9 | K185: 6609785.9 | L185: 7396983.9 | M185: 7378626.3 | N185: 8066369.5 | O185: 7376221.8 | P185: 6786824.3 | Q185: 7521165 | R185: 7502118.1 | S185: 7172332.7 | T185: 7109735.9 | U185: 7144174.6 | V185: 6485981.8 | W185: 6920206.7 | X185: 7612664.3 | Y185: 7332747.7 | Z185: 7044135.1
A186: 184 | B186: Oakville Assembly Complex, Ford Motor Company of Canada, Limited | C186: M | G186: 7666974.2 | H186: 6982670.2 | I186: 6640095.9 | J186: 6194497.9 | K186: 6609785.9 | L186: 7396983.9 | M186: 7378626.3 | N186: 8066369.5 | O186: 7376221.8 | P186: 6786824.3 | Q186: 7521165 | R186: 7502118.1 | S186: 7172332.7 | T186: 7109735.9 | U186: 7144174.6 | V186: 6485981.8 | W186: 6920206.7 | X186: 7612664.3 | Y186: 7332747.7 | Z186: 7044135.1
A187: 185 | B187: Ford Motor Co of Canada Ltd | C187: M | G187: 7666974.2 | H187: 6982670.2 | I187: 6640095.9 | J187: 6194497.9 | K187: 6609785.9 | L187: 7396983.9 | M187: 7378626.3 | N187: 8066369.5 | O187: 7376221.8 | P187: 6786824.3 | Q187: 7521165 | R187: 7502118.1 | S187: 7172332.7 | T187: 7109735.9 | U187: 7144174.6 | V187: 6485981.8 | W187: 6920206.7 | X187: 7612664.3 | Y187: 7332747.7 | Z187: 7044135.1
A188: 186 | B188: GM Oshawa Assembly | C188: M | G188: 7666974.2 | H188: 6982670.2 | I188: 6640095.9 | J188: 6194497.9 | K188: 6609785.9 | L188: 7396983.9 | M188: 7378626.3 | N188: 8066369.5 | O188: 7376221.8 | P188: 6786824.3 | Q188: 7521165 | R188: 7502118.1 | S188: 7172332.7 | T188: 7109735.9 | U188: 7144174.6 | V188: 6485981.8 | W188: 6920206.7 | X188: 7612664.3 | Y188: 7332747.7 | Z188: 7044135.1
A189: 187 | B189: General Motors of Canada Company | C189: M | G189: 7666974.2 | H189: 6982670.2 | I189: 6640095.9 | J189: 6194497.9 | K189: 6609785.9 | L189: 7396983.9 | M189: 7378626.3 | N189: 8066369.5 | O189: 7376221.8 | P189: 6786824.3 | Q189: 7521165 | R189: 7502118.1 | S189: 7172332.7 | T189: 7109735.9 | U189: 7144174.6 | V189: 6485981.8 | W189: 6920206.7 | X189: 7612664.3 | Y189: 7332747.7 | Z189: 7044135.1
A190: 188 | B190: GM CAMI Assembly | C190: M | G190: 7666974.2 | H190: 6982670.2 | I190: 6640095.9 | J190: 6194497.9 | K190: 6609785.9 | L190: 7396983.9 | M190: 7378626.3 | N190: 8066369.5 | O190: 7376221.8 | P190: 6786824.3 | Q190: 7521165 | R190: 7502118.1 | S190: 7172332.7 | T190: 7109735.9 | U190: 7144174.6 | V190: 6485981.8 | W190: 6920206.7 | X190: 7612664.3 | Y190: 7332747.7 | Z190: 7044135.1
A191: 189 | B191: Honda of Canada Mfg. | C191: M | G191: 7666974.2 | H191: 6982670.2 | I191: 6640095.9 | J191: 6194497.9 | K191: 6609785.9 | L191: 7396983.9 | M191: 7378626.3 | N191: 8066369.5 | O191: 7376221.8 | P191: 6786824.3 | Q191: 7521165 | R191: 7502118.1 | S191: 7172332.7 | T191: 7109735.9 | U191: 7144174.6 | V191: 6485981.8 | W191: 6920206.7 | X191: 7612664.3 | Y191: 7332747.7 | Z191: 7044135.1
A192: 190 | B192: Honda of Canada Manufacturing Gate B Rafid | C192: M | G192: 7666974.2 | H192: 6982670.2 | I192: 6640095.9 | J192: 6194497.9 | K192: 6609785.9 | L192: 7396983.9 | M192: 7378626.3 | N192: 8066369.5 | O192: 7376221.8 | P192: 6786824.3 | Q192: 7521165 | R192: 7502118.1 | S192: 7172332.7 | T192: 7109735.9 | U192: 7144174.6 | V192: 6485981.8 | W192: 6920206.7 | X192: 7612664.3 | Y192: 7332747.7 | Z192: 7044135.1
...

Sheet Node_stochastic_40
A1: nodeNum | B1: City | C1: type | D1: f_i | E1: capacity | F1: o_i | G1: d_1 | H1: d_2 | I1: d_3 | J1: d_4 | K1: d_5 | L1: d_6 | M1: d_7 | N1: d_8 | O1: d_9 | P1: d_10 | Q1: d_11 | R1: d_12 | S1: d_13 | T1: d_14 | U1: d_15 | V1: d_16 | W1: d_17 | X1: d_18 | Y1: d_19 | Z1: d_20 | AA1: si | AB1: si_num | AC1: s_1 | AD1: s_2 | AE1: s_3 | AF1: s_4 | AG1: s_5 | AH1: s_6 | AI1: s_7 | AJ1: s_8 | AK1: s_9 | AL1: s_10 | AM1: s_11 | AN1: s_12 | AO1: s_13 | AP1: s_14 | AQ1: s_15 | AR1: s_16 | AS1: s_17 | AT1: s_18 | AU1: s_19 | AV1: s_20
A2: 0 | B2: Acton | C2: C | AA2: 52750 | AB2: =AA2*25 -> 1318750 | AC2: 32589.185 | AD2: 1374516 | AE2: 1493355.3 | AF2: 379522.5 | AG2: 1472881.1 | AH2: 2046174.2 | AI2: 1334067.7 | AJ2: 1391933.5 | AK2: 872714.07 | AL2: 1325737.3 | AM2: 1516664.1 | AN2: 2248980.1 | AO2: 1106971 | AP2: 1595073.6 | AQ2: 2018780.3 | AR2: 1514245.6 | AS2: 2024342.4 | AT2: 1746040.6 | AU2: 749017.55 | AV2: 1402575.2
A3: 1 | B3: Arnprior | C3: C | AA3: 29860 | AB3: =AA3*25 -> 746500 | AC3: 1016422.2 | AD3: 713232.74 | AE3: 622585.65 | AF3: 808298.94 | AG3: 669775.18 | AH3: 383659.08 | AI3: 649750.04 | AJ3: 1159797.3 | AK3: 473647.46 | AL3: 1249529.4 | AM3: 496890.37 | AN3: 678932.47 | AO3: 484658.17 | AP3: 8758.5321 | AQ3: 784126.74 | AR3: 911263.56 | AS3: 716118.05 | AT3: 449189.88 | AU3: 592690.51 | AV3: 678086.64
A4: 2 | B4: Arthur | C4: C | AA4: 44602 | AB4: =AA4*25 -> 1115050 | AC4: 1512057.9 | AD4: 1839539.8 | AE4: 769139.8 | AF4: 131847.87 | AG4: 2088594.1 | AH4: 690701.67 | AI4: 845387.83 | AJ4: 1083161.1 | AK4: 1182755.9 | AL4: 296575.92 | AM4: 1004112.6 | AN4: 1206822.4 | AO4: 543010.05 | AP4: 1362514.2 | AQ4: 595447.17 | AR4: 639985.38 | AS4: 1134597.6 | AT4: 1285459.4 | AU4: 377232.81 | AV4: 1382866.3
A5: 3 | B5: Aurora | C5: C | AA5: 110396 | AB5: =AA5*25 -> 2759900 | AC5: 4438080 | AD5: 3346340.1 | AE5: 2215726.1 | AF5: 2207991.4 | AG5: 3249324.3 | AH5: 3499138.5 | AI5: 3995807.6 | AJ5: 3769882.4 | AK5: 1542418.9 | AL5: 2068185.3 | AM5: 2586158 | AN5: 2635734.4 | AO5: 1206859.7 | AP5: 0 | AQ5: 2719598.3 | AR5: 2484171.9 | AS5: 1057517.1 | AT5: 2055686.1 | AU5: 492632.23 | AV5: 2010795.5
A6: 4 | B6: Beaverton | C6: C | AA6: 77661 | AB6: =AA6*25 -> 1941525 | AC6: 1305821.8 | AD6: 468645.4 | AE6: 2132638.4 | AF6: 1861200.9 | AG6: 2037306.6 | AH6: 1323588.6 | AI6: 2049156.2 | AJ6: 689344.66 | AK6: 1234595.4 | AL6: 1561441.7 | AM6: 2206704.7 | AN6: 597251.47 | AO6: 2153146.1 | AP6: 1398294.1 | AQ6: 1837185.7 | AR6: 1988749.5 | AS6: 1590644.6 | AT6: 1708655.9 | AU6: 2588499.7 | AV6: 1850311
A7: 5 | B7: Bowmanville | C7: C | AA7: 77661 | AB7: =AA7*25 -> 1941525 | AC7: 1287852.8 | AD7: 2821996.6 | AE7: 1003621.5 | AF7: 2951553.6 | AG7: 2013129.8 | AH7: 1259886.7 | AI7: 2243465.9 | AJ7: 1644100 | AK7: 1388708.3 | AL7: 1368488.5 | AM7: 1591657 | AN7: 2083518.9 | AO7: 540375.24 | AP7: 3296981.5 | AQ7: 3236856.7 | AR7: 3476451.5 | AS7: 895275.24 | AT7: 1490791.4 | AU7: 2096573.4 | AV7: 0
A8: 6 | B8: Bradford | C8: C | AA8: 103343 | AB8: =AA8*25 -> 2583575 | AC8: 1630896.1 | AD8: 3108805.7 | AE8: 1643452.4 | AF8: 1173201.3 | AG8: 907928.43 | AH8: 3429360.6 | AI8: 2534194.9 | AJ8: 1368922.2 | AK8: 2364807.8 | AL8: 2340586.9 | AM8: 2668725.9 | AN8: 3848991.2 | AO8: 2516919 | AP8: 2389470.2 | AQ8: 5330685.2 | AR8: 1431297.4 | AS8: 2784743.8 | AT8: 1461336.4 | AU8: 2139043.1 | AV8: 3772252.5
A9: 7 | B9: Brampton | C9: C | AA9: 371033 | AB9: =AA9*25 -> 9275825 | AC9: 9060466.3 | AD9: 10867035 | AE9: 2081267.8 | AF9: 4550730.1 | AG9: 14589935 | AH9: 12763535 | AI9: 10386660 | AJ9: 13068518 | AK9: 16294634 | AL9: 13671574 | AM9: 11351611 | AN9: 7158886.2 | AO9: 10511763 | AP9: 11578977 | AQ9: 3475790 | AR9: 7091780.5 | AS9: 8458205.6 | AT9: 8652092.6 | AU9: 9739994.4 | AV9: 8699708.4
A10: 8 | B10: Brantford | C10: C | AA10: 83809 | AB10: =AA10*25 -> 2095225 | AC10: 1856473.9 | AD10: 2140396.3 | AE10: 2169642.5 | AF10: 3004982.9 | AG10: 2664642.8 | AH10: 2680296.4 | AI10: 925018.2 | AJ10: 2191045.3 | AK10: 3490476.7 | AL10: 953096.65 | AM10: 2333726.8 | AN10: 1795723 | AO10: 683085.61 | AP10: 1723438.8 | AQ10: 1783646.6 | AR10: 1222668.1 | AS10: 1167576.7 | AT10: 3529457.5 | AU10: 1458465.5 | AV10: 1649057.1
A11: 9 | B11: Caistor Centre | C11: C | AA11: 4704 | AB11: =AA11*25 -> 117600 | AC11: 77280.342 | AD11: 136398.11 | AE11: 50180.232 | AF11: 96056.449 | AG11: 92603.942 | AH11: 120115.65 | AI11: 74758.387 | AJ11: 195982.76 | AK11: 77683.815 | AL11: 188326.3 | AM11: 140040.92 | AN11: 193385.41 | AO11: 110997.63 | AP11: 119350.38 | AQ11: 106156.35 | AR11: 211005.81 | AS11: 118153.63 | AT11: 178313.22 | AU11: 77401.82 | AV11: 158481.92
A12: 10 | B12: Caledon | C12: C | AA12: 371033 | AB12: =AA12*25 -> 9275825 | AC12: 6792598.1 | AD12: 8271083 | AE12: 7942485.6 | AF12: 6942485.2 | AG12: 14616009 | AH12: 9517214.5 | AI12: 9924255.2 | AJ12: 13540421 | AK12: 6428640.4 | AL12: 4861919 | AM12: 2721759.1 | AN12: 12916029 | AO12: 12840714 | AP12: 9328115.9 | AQ12: 2656556.7 | AR12: 5495087.1 | AS12: 5073803.1 | AT12: 6345258.2 | AU12: 10345685 | AV12: 9645910.7
A13: 11 | B13: Cambridge | C13: C | AA13: 107823 | AB13: =AA13*25 -> 2695575 | AC13: 2064138.1 | AD13: 2273926.3 | AE13: 2632666.5 | AF13: 3792088.1 | AG13: 2892882.1 | AH13: 1843449.6 | AI13: 1867611 | AJ13: 1736813.8 | AK13: 1199150.4 | AL13: 1604268.2 | AM13: 2548904.9 | AN13: 3842003 | AO13: 1758149.8 | AP13: 3646526.1 | AQ13: 1444966.6 | AR13: 3299457.2 | AS13: 1394078.9 | AT13: 1854542.4 | AU13: 1832009.1 | AV13: 1384280.8
... A78: 76 | B78: Windsor | C78: C | AA78: 56665 | AB78: =AA78*25 -> 1416625 | AC78: 1172403.7 | AD78: 2311809.6 | AE78: 1900181.2 | AF78: 938153.24 | AG78: 1556248.6 | AH78: 735235.37 | AI78: 1553873.7 | AJ78: 1634444 | AK78: 691324.79 | AL78: 1616934.3 | AM78: 2055657.3 | AN78: 1103715.8 | AO78: 1293357 | AP78: 1784984.4 | AQ78: 868355.23 | AR78: 1887736.8 | AS78: 1830114.9 | AT78: 1276599.3 | AU78: 2044748.6 | AV78: 1403823.1
A79: 77 | B79: Toronto | C79: R | D79: 2018592.8 | E79: 6000000000 | F79: 0.02
A80: 78 | B80: Ottawa | C80: R | D80: 2012544.2 | E80: 6000000000 | F80: 0.02
A81: 79 | B81: Mississauga | C81: R | D81: 2035869.4 | E81: 6000000000 | F81: 0.02
A82: 80 | B82: Brampton | C82: R | D82: 2035869.4 | E82: 6000000000 | F82: 0.02
A83: 81 | B83: Hamilton | C83: R | D83: 2035755.2 | E83: 6000000000 | F83: 0.02
A84: 82 | B84: London | C84: R | D84: 2019654.7 | E84: 6000000000 | F84: 0.02
A85: 83 | B85: Markham | C85: R | D85: 2035755.2 | E85: 6000000000 | F85: 0.02
A86: 84 | B86: Vaughan | C86: R | D86: 2016415 | E86: 6000000000 | F86: 0.02
A87: 85 | B87: Kitchener | C87: R | D87: 2025276.7 | E87: 6000000000 | F87: 0.02
A88: 86 | B88: Windsor | C88: R | D88: 2021880.1 | E88: 6000000000 | F88: 0.02
A89: 87 | B89: Oakville | C89: R | D89: 2054614.9 | E89: 6000000000 | F89: 0.02
A90: 88 | B90: Richmond Hill | C90: R | D90: 2035755.2 | E90: 6000000000 | F90: 0.02
... A179: 177 | B179: Penetanguishene | C179: R | D179: 2016415 | E179: 6000000000 | F179: 0.02
A180: 178 | B180: Fiat Chrysler Automobiles, Brampton Assembly Plant | C180: M | G180: =SUM(AC2:AC78)*0.8/18 -> 7907664.4 | H180: =SUM(AD2:AD78)*0.8/18 -> 6812667.8 | I180: =SUM(AE2:AE78)*0.8/18 -> 6597757.6 | J180: =SUM(AF2:AF78)*0.8/18 -> 6275788.9 | K180: =SUM(AG2:AG78)*0.8/18 -> 8238351.2 | L180: =SUM(AH2:AH78)*0.8/18 -> 6357718.7 | M180: =SUM(AI2:AI78)*0.8/18 -> 6151698.5 | N180: =SUM(AJ2:AJ78)*0.8/18 -> 8129620.4 | ... Z180: =SUM(AV2:AV78)*0.8/18 -> 5988782.7
A181: 179 | B181: Stellantis (Chrysler) Windsor | C181: M | G181: 7906471.3 | H181: 6791130.9 | I181: 6597757.6 | J181: 6275788.9 | K181: 8238351.2 | L181: 6357718.7 | M181: 6151698.5 | N181: 8129620.4 | O181: 7566761.7 | P181: 7441670.5 | Q181: 6836345.7 | R181: 7707299.3 | S181: 6456457.8 | T181: 8355111.2 | U181: 7078791.1 | V181: 6389460 | W181: 7581924.2 | X181: 7142806.3 | Y181: 6325992 | Z181: 5980730.8
A182: 180 | B182: Oakville Assembly Complex, Ford Motor Company of Canada, Limited | C182: M | G182: 7906471.3 | H182: 6791130.9 | I182: 6597757.6 | J182: 6275788.9 | K182: 8238351.2 | L182: 6357718.7 | M182: 6151698.5 | N182: 8129620.4 | O182: 7566761.7 | P182: 7441670.5 | Q182: 6836345.7 | R182: 7707299.3 | S182: 6456457.8 | T182: 8355111.2 | U182: 7078791.1 | V182: 6389460 | W182: 7581924.2 | X182: 7142806.3 | Y182: 6325992 | Z182: 5980730.8
A183: 181 | B183: St. Thomas Assembly Plant | C183: M | G183: 7906471.3 | H183: 6791130.9 | I183: 6597757.6 | J183: 6275788.9 | K183: 8238351.2 | L183: 6357718.7 | M183: 6151698.5 | N183: 8129620.4 | O183: 7566761.7 | P183: 7441670.5 | Q183: 6836345.7 | R183: 7707299.3 | S183: 6456457.8 | T183: 8355111.2 | U183: 7078791.1 | V183: 6389460 | W183: 7581924.2 | X183: 7142806.3 | Y183: 6325992 | Z183: 5980730.8
A184: 182 | B184: Ford Motor Co. Windsor Engine Plant | C184: M | G184: 7906471.3 | H184: 6791130.9 | I184: 6597757.6 | J184: 6275788.9 | K184: 8238351.2 | L184: 6357718.7 | M184: 6151698.5 | N184: 8129620.4 | O184: 7566761.7 | P184: 7441670.5 | Q184: 6836345.7 | R184: 7707299.3 | S184: 6456457.8 | T184: 8355111.2 | U184: 7078791.1 | V184: 6389460 | W184: 7581924.2 | X184: 7142806.3 | Y184: 6325992 | Z184: 5980730.8
A185: 183 | B185: Ford | C185: M | G185: 7906471.3 | H185: 6791130.9 | I185: 6597757.6 | J185: 6275788.9 | K185: 8238351.2 | L185: 6357718.7 | M185: 6151698.5 | N185: 8129620.4 | O185: 7566761.7 | P185: 7441670.5 | Q185: 6836345.7 | R185: 7707299.3 | S185: 6456457.8 | T185: 8355111.2 | U185: 7078791.1 | V185: 6389460 | W185: 7581924.2 | X185: 7142806.3 | Y185: 6325992 | Z185: 5980730.8
A186: 184 | B186: Oakville Assembly Complex, Ford Motor Company of Canada, Limited | C186: M | G186: 7906471.3 | H186: 6791130.9 | I186: 6597757.6 | J186: 6275788.9 | K186: 8238351.2 | L186: 6357718.7 | M186: 6151698.5 | N186: 8129620.4 | O186: 7566761.7 | P186: 7441670.5 | Q186: 6836345.7 | R186: 7707299.3 | S186: 6456457.8 | T186: 8355111.2 | U186: 7078791.1 | V186: 6389460 | W186: 7581924.2 | X186: 7142806.3 | Y186: 6325992 | Z186: 5980730.8
A187: 185 | B187: Ford Motor Co of Canada Ltd | C187: M | G187: 7906471.3 | H187: 6791130.9 | I187: 6597757.6 | J187: 6275788.9 | K187: 8238351.2 | L187: 6357718.7 | M187: 6151698.5 | N187: 8129620.4 | O187: 7566761.7 | P187: 7441670.5 | Q187: 6836345.7 | R187: 7707299.3 | S187: 6456457.8 | T187: 8355111.2 | U187: 7078791.1 | V187: 6389460 | W187: 7581924.2 | X187: 7142806.3 | Y187: 6325992 | Z187: 5980730.8
